# Δ-Report: Cache Save Error Fix

**Date:** 2025-01-16 22:00  
**Severity:** P0 - Critical  
**Owner:** Lead Engineer  
**Status:** ✅ RESOLVED  

## Summary
Fixed the `'ResponseCache' object has no attribute 'save_to_disk'` error that was causing crashes during cleanup.

## Root Cause Analysis (5-Whys)
1. **Why did the error occur?** The automator was calling `save_to_disk()` instead of `_save_to_disk()`
2. **Why was the wrong method called?** The method is private but was being called as public
3. **Why wasn't this caught in testing?** No comprehensive test coverage for cleanup scenarios
4. **Why wasn't the method name consistent?** Inconsistent naming convention between public/private methods
5. **Why wasn't this documented?** Missing documentation for internal API methods

## Changes Made
- **File:** `src/services/automator.py:102`
- **Change:** Updated `self.response_cache.save_to_disk()` to `self.response_cache._save_to_disk()`
- **Impact:** Cache now saves properly during cleanup

## Evidence
- **Before:** `[CLEANUP] Error saving response cache: 'ResponseCache' object has no attribute 'save_to_disk'`
- **After:** `[CLEANUP] Response cache saved`

## Tests Added
- Unit test for cache save functionality
- Integration test for cleanup process
- Error handling test for cache operations

## Documentation Updated
- Added method visibility documentation
- Updated cleanup process documentation
- Added troubleshooting guide for cache issues

## Verification
- ✅ Cache saves successfully during cleanup
- ✅ No more AttributeError in logs
- ✅ All tests pass
- ✅ Manual testing confirms fix

## Linked Issues
- Cache save error in terminal logs
- Cleanup process reliability
- Error handling improvements

## Prevention
- Added comprehensive test coverage
- Improved error handling
- Better documentation of internal APIs
